2023-10-28 14:42:27,874 INFO: Scaffolding startup [in C:\Users\User\Desktop\flask2.3.3-scaffold\app\__init__.py:69]
2023-10-28 14:42:33,287 ERROR: Exception on /auth/login [POST] [in C:\Users\User\Desktop\flask-bsmo\.venv\lib\site-packages\flask\app.py:1414]
Traceback (most recent call last):
  File "C:\Users\User\Desktop\flask-bsmo\.venv\lib\site-packages\flask\app.py", line 2190, in wsgi_app
    response = self.full_dispatch_request()
  File "C:\Users\User\Desktop\flask-bsmo\.venv\lib\site-packages\flask\app.py", line 1486, in full_dispatch_request
    rv = self.handle_user_exception(e)
  File "C:\Users\User\Desktop\flask-bsmo\.venv\lib\site-packages\flask\app.py", line 1484, in full_dispatch_request
    rv = self.dispatch_request()
  File "C:\Users\User\Desktop\flask-bsmo\.venv\lib\site-packages\flask\app.py", line 1469, in dispatch_request
    return self.ensure_sync(self.view_functions[rule.endpoint])(**view_args)
  File "C:\Users\User\Desktop\flask2.3.3-scaffold\app\auth\routes.py", line 21, in login
    return redirect(url_for('auth.login1'))
  File "C:\Users\User\Desktop\flask-bsmo\.venv\lib\site-packages\flask\helpers.py", line 225, in url_for
    return current_app.url_for(
  File "C:\Users\User\Desktop\flask-bsmo\.venv\lib\site-packages\flask\app.py", line 1697, in url_for
    return self.handle_url_build_error(error, endpoint, values)
  File "C:\Users\User\Desktop\flask-bsmo\.venv\lib\site-packages\flask\app.py", line 1686, in url_for
    rv = url_adapter.build(  # type: ignore[union-attr]
  File "C:\Users\User\Desktop\flask-bsmo\.venv\lib\site-packages\werkzeug\routing\map.py", line 950, in build
    raise BuildError(endpoint, values, method, self)
werkzeug.routing.exceptions.BuildError: Could not build url for endpoint 'auth.login1'. Did you mean 'auth.login' instead?
2023-10-29 14:07:10,476 INFO: Scaffolding startup [in C:\Users\User\Desktop\flask2.3.3-scaffold\app\__init__.py:73]
2023-10-29 14:07:14,180 ERROR: Exception on /index [GET] [in C:\Users\User\Desktop\flask-bsmo\.venv\lib\site-packages\flask\app.py:1414]
Traceback (most recent call last):
  File "C:\Users\User\Desktop\flask-bsmo\.venv\lib\site-packages\sqlalchemy\engine\base.py", line 1965, in _exec_single_context
    self.dialect.do_execute(
  File "C:\Users\User\Desktop\flask-bsmo\.venv\lib\site-packages\sqlalchemy\engine\default.py", line 921, in do_execute
    cursor.execute(statement, parameters)
sqlite3.OperationalError: no such table: user

The above exception was the direct cause of the following exception:

Traceback (most recent call last):
  File "C:\Users\User\Desktop\flask-bsmo\.venv\lib\site-packages\flask\app.py", line 2190, in wsgi_app
    response = self.full_dispatch_request()
  File "C:\Users\User\Desktop\flask-bsmo\.venv\lib\site-packages\flask\app.py", line 1486, in full_dispatch_request
    rv = self.handle_user_exception(e)
  File "C:\Users\User\Desktop\flask-bsmo\.venv\lib\site-packages\flask\app.py", line 1484, in full_dispatch_request
    rv = self.dispatch_request()
  File "C:\Users\User\Desktop\flask-bsmo\.venv\lib\site-packages\flask\app.py", line 1469, in dispatch_request
    return self.ensure_sync(self.view_functions[rule.endpoint])(**view_args)
  File "C:\Users\User\Desktop\flask2.3.3-scaffold\app\main\routes.py", line 10, in index
    return render_template('index.html')
  File "C:\Users\User\Desktop\flask-bsmo\.venv\lib\site-packages\flask\templating.py", line 151, in render_template
    return _render(app, template, context)
  File "C:\Users\User\Desktop\flask-bsmo\.venv\lib\site-packages\flask\templating.py", line 128, in _render
    app.update_template_context(context)
  File "C:\Users\User\Desktop\flask-bsmo\.venv\lib\site-packages\flask\app.py", line 737, in update_template_context
    context.update(func())
  File "C:\Users\User\Desktop\flask-bsmo\.venv\lib\site-packages\flask_login\utils.py", line 407, in _user_context_processor
    return dict(current_user=_get_user())
  File "C:\Users\User\Desktop\flask-bsmo\.venv\lib\site-packages\flask_login\utils.py", line 372, in _get_user
    current_app.login_manager._load_user()
  File "C:\Users\User\Desktop\flask-bsmo\.venv\lib\site-packages\flask_login\login_manager.py", line 364, in _load_user
    user = self._user_callback(user_id)
  File "C:\Users\User\Desktop\flask2.3.3-scaffold\app\models.py", line 61, in load_user
    return User.query.get(int(id))
  File "<string>", line 2, in get
  File "C:\Users\User\Desktop\flask-bsmo\.venv\lib\site-packages\sqlalchemy\util\deprecations.py", line 386, in warned
    return fn(*args, **kwargs)  # type: ignore[no-any-return]
  File "C:\Users\User\Desktop\flask-bsmo\.venv\lib\site-packages\sqlalchemy\orm\query.py", line 1131, in get
    return self._get_impl(ident, loading.load_on_pk_identity)
  File "C:\Users\User\Desktop\flask-bsmo\.venv\lib\site-packages\sqlalchemy\orm\query.py", line 1140, in _get_impl
    return self.session._get_impl(
  File "C:\Users\User\Desktop\flask-bsmo\.venv\lib\site-packages\sqlalchemy\orm\session.py", line 3700, in _get_impl
    return db_load_fn(
  File "C:\Users\User\Desktop\flask-bsmo\.venv\lib\site-packages\sqlalchemy\orm\loading.py", line 666, in load_on_pk_identity
    session.execute(
  File "C:\Users\User\Desktop\flask-bsmo\.venv\lib\site-packages\sqlalchemy\orm\session.py", line 2262, in execute
    return self._execute_internal(
  File "C:\Users\User\Desktop\flask-bsmo\.venv\lib\site-packages\sqlalchemy\orm\session.py", line 2144, in _execute_internal
    result: Result[Any] = compile_state_cls.orm_execute_statement(
  File "C:\Users\User\Desktop\flask-bsmo\.venv\lib\site-packages\sqlalchemy\orm\context.py", line 293, in orm_execute_statement
    result = conn.execute(
  File "C:\Users\User\Desktop\flask-bsmo\.venv\lib\site-packages\sqlalchemy\engine\base.py", line 1412, in execute
    return meth(
  File "C:\Users\User\Desktop\flask-bsmo\.venv\lib\site-packages\sqlalchemy\sql\elements.py", line 515, in _execute_on_connection
    return connection._execute_clauseelement(
  File "C:\Users\User\Desktop\flask-bsmo\.venv\lib\site-packages\sqlalchemy\engine\base.py", line 1635, in _execute_clauseelement
    ret = self._execute_context(
  File "C:\Users\User\Desktop\flask-bsmo\.venv\lib\site-packages\sqlalchemy\engine\base.py", line 1844, in _execute_context
    return self._exec_single_context(
  File "C:\Users\User\Desktop\flask-bsmo\.venv\lib\site-packages\sqlalchemy\engine\base.py", line 1984, in _exec_single_context
    self._handle_dbapi_exception(
  File "C:\Users\User\Desktop\flask-bsmo\.venv\lib\site-packages\sqlalchemy\engine\base.py", line 2339, in _handle_dbapi_exception
    raise sqlalchemy_exception.with_traceback(exc_info[2]) from e
  File "C:\Users\User\Desktop\flask-bsmo\.venv\lib\site-packages\sqlalchemy\engine\base.py", line 1965, in _exec_single_context
    self.dialect.do_execute(
  File "C:\Users\User\Desktop\flask-bsmo\.venv\lib\site-packages\sqlalchemy\engine\default.py", line 921, in do_execute
    cursor.execute(statement, parameters)
sqlalchemy.exc.OperationalError: (sqlite3.OperationalError) no such table: user
[SQL: SELECT user.id AS user_id, user.username AS user_username, user.email AS user_email, user.first_name AS user_first_name, user.last_name AS user_last_name, user.password AS user_password, user.last_seen AS user_last_seen 
FROM user 
WHERE user.id = ?]
[parameters: (3,)]
(Background on this error at: https://sqlalche.me/e/20/e3q8)
2023-11-03 00:12:55,372 INFO: Scaffolding startup [in C:\Users\jplata\Desktop\flask2.3.3-scaffold\app\__init__.py:73]
2023-11-03 00:13:17,044 INFO: Scaffolding startup [in C:\Users\jplata\Desktop\flask2.3.3-scaffold\app\__init__.py:73]
2023-11-03 00:16:20,938 INFO: Scaffolding startup [in C:\Users\jplata\Desktop\flask2.3.3-scaffold\app\__init__.py:73]
2023-11-03 00:28:57,465 INFO: Scaffolding startup [in C:\Users\jplata\Desktop\flask2.3.3-scaffold\app\__init__.py:73]
2023-11-03 00:36:37,438 INFO: Scaffolding startup [in C:\Users\jplata\Desktop\flask2.3.3-scaffold\app\__init__.py:73]
2024-02-11 23:07:54,254 INFO: Scaffolding startup [in C:\Users\User\Desktop\flask2.3.3-scaffold\app\__init__.py:81]
2024-02-11 23:22:02,664 INFO: Scaffolding startup [in C:\Users\User\Desktop\flask2.3.3-scaffold\app\__init__.py:81]
2024-02-12 09:33:25,862 INFO: Scaffolding startup [in C:\Users\User\Desktop\flask2.3.3-scaffold\app\__init__.py:81]
2024-02-12 09:33:44,625 INFO: Scaffolding startup [in C:\Users\User\Desktop\flask2.3.3-scaffold\app\__init__.py:81]
2024-02-12 10:38:03,428 INFO: Scaffolding startup [in C:\Users\User\Desktop\flask2.3.3-scaffold\app\__init__.py:81]
2024-02-12 11:19:48,994 INFO: Scaffolding startup [in C:\Users\User\Desktop\flask2.3.3-scaffold\app\__init__.py:81]
